// Summary for: /mnt/c/dev/buccancs/external/ShimmerCapturePure/sources/io/grpc/netty/shaded/io/netty/util/internal/PromiseNotificationUtil.java
// Size: 2165 bytes
// Modified: 2025-10-21 16:32:04.602780300 +0100

package io.grpc.netty.shaded.io.netty.util.internal;

import io.grpc.netty.shaded.io.netty.util.concurrent.Promise;
import io.grpc.netty.shaded.io.netty.util.internal.logging.InternalLogger;

/* loaded from: classes3.dex */
public final class PromiseNotificationUtil {
    private PromiseNotificationUtil() {
    }

    public static void tryCancel(Promise<?> promise, InternalLogger internalLogger) {
        if (promise.cancel(false) || internalLogger == null) {
            return;
        }
        Throwable thCause = promise.cause();
        if (thCause == null) {
            internalLogger.warn("Failed to cancel promise because it has succeeded already: {}", promise);
        } else {
            internalLogger.warn("Failed to cancel promise because it has failed already: {}, unnotified cause:", promise, thCause);
        }
    }

    /* JADX WARN: Multi-variable type inference failed */
    public static <V> void trySuccess(Promise<? super V> promise, V v, InternalLogger internalLogger) {
        if (promise.trySuccess(v) || internalLogger == null) {
            return;
        }
        Throwable thCause = promise.cause();
        if (thCause == null) {
            internalLogger.warn("Failed to mark a promise as success because it has succeeded already: {}", promise);
        } else {
            internalLogger.warn("Failed to mark a promise as success because it has failed already: {}, unnotified cause:", promise, thCause);
        }
    }

    public static void tryFailure(Promise<?> promise, Throwable th, InternalLogger internalLogger) {
        if (promise.tryFailure(th) || internalLogger == null) {
            return;
        }
        Throwable thCause = promise.cause();
        if (thCause == null) {
            internalLogger.warn("Failed to mark a promise as failure because it has succeeded already: {}", promise, th);
        } else if (internalLogger.isWarnEnabled()) {
            internalLogger.warn("Failed to mark a promise as failure because it has failed already: {}, unnotified cause: {}", promise, ThrowableUtil.stackTraceToString(thCause), th);
        }
    }
}
